Workbook

Sheet yardımcı
A1: Poz No | B1: Poz tanımı | C1: Birim Ağ. | D1: Miktar | F1: ALTYÜKLENİCİ | H1: klavuz | J1: İŞİN ADI | K1: ALT YÜKLENİCİ | L1: KONTROLÜ YAPAN | M1: TUTANAK TARİHİ | N1: HAKEDİŞ KONTROL TUTANAĞI NUMARASI | O1: HAKEDİŞE GİREN POZ NO | P1: HAKEDİŞE GİREN POZ ADI | Q1: SAHA İMALARINA GÖRE POZ NO | R1: SAHA İMALATINA GÖRE POZ ADI | S1: MİKTAR | T1: TAŞEREON SAHA İMALAT FARKI | U1: TUTANAK AÇIKLAMASI
A2: 40.1.1 | B2: TUVENAN DOLGULU KABLO KANALI | F2: ALPTUĞ | H2: https://ersinkucukcamur.github.io/saharaporu/ | J2: =+KAPAK!D5 -> 0 | K2: =+KAPAK!M3 -> 0 | L2: =+KAPAK!M28 -> TESPİTİ YAPAN | M2: =+KAPAK!D3 -> 46048 | N2: =+KAPAK!D4 -> 0 | O2: 40.1.1 | P2: =+VLOOKUP(O2,A:B,2,0) -> TUVENAN DOLGULU KABLO KANALI | U2: Ölçüleri eksik kazılan kanal
A3: 40.2 | B3: TOPRAK DOLGULU KABLO KANALI | F3: ANKARA SCADA | H3: *yukarıdaki bağlantı ile saha raporu hazırlama yardımcısına ulaşabilirsiniz. | J3: =+KAPAK!D5 -> 0 | K3: =+KAPAK!M3 -> 0 | L3: =+KAPAK!M28 -> TESPİTİ YAPAN | M3: =+KAPAK!D3 -> 46048 | N3: =+KAPAK!D4 -> 0 | O3: 40.1.1 | P3: =+VLOOKUP(O3,A:B,2,0) -> TUVENAN DOLGULU KABLO KANALI | Q3: 40.2 | R3: =+VLOOKUP(Q3,A:B,2,0) -> TOPRAK DOLGULU KABLO KANALI | U3: Geri dolgu yapılan kanal
A4: 40.2.4 | B4: PARKE KAPLAMALI TUVENAN KABLO KANALI | F4: ARIÇAM | H4: *tespit edilen uygunsuzluklar sahada sözlü olarak bildirilmesine rağmen geri dönüş yapılmaz ise ertesi gün tutanağa dönüştürüp ilgili saha personelinin de bilgisi ile taşerona iletelim. | J4: =+KAPAK!D5 -> 0 | K4: =+KAPAK!M3 -> 0 | L4: =+KAPAK!M28 -> TESPİTİ YAPAN | M4: =+KAPAK!D3 -> 46048 | N4: =+KAPAK!D4 -> 0 | O4: 5.5.1-1 | P4: =+VLOOKUP(O4,A:B,2,0) -> I-Şehir içi A.G ve O.G Müşterek Direkler | U4: Temeli uygun olmayan direkler (kg)
A5: 40.2.5 | B5: BETON KAPLAMALI TUVENAN KABLO KANALI | F5: ARSLAN | H5: *PROJE menüsü içerisinden dxf ve kmz dosyaları yüklenebilir. (dxf için uygun projeksiyon seçilmesi lazım)
A6: 5.5.1-1 | B6: I-Şehir içi A.G ve O.G Müşterek Direkler | F6: ASDEM | H6: *FOTO menüsünden, içerisinde exif konum verileri bulunan fotoğraflar klasörden ya da seçilerek yüklendiğinde harita üzerinde çekildiği konumda simge olarak belirecektir. Konum verisi olmayan fotoğrafları MANUEL konum butonuna tıkladıktan sonra harita üzerinde olması gereken yere tıklayarak tek tek yüklemek gerekmektedir.
A7: 5.5.1-5 | B7: 10I - Uzun Tip AG Demir Direk | C7: 207 | F7: ASMİN | H7: *Yüklenen fotoğraflar simgesine tıklanarak ön izleme penceresinde açılabilir ve tutanağa eklenecek olanlar seç butonu ile işaretlendiğinde simgesi değişerek seçim sırasına göre numaralandırılır.
A8: 5.5.1-6 | B8: 10U - Uzun Tip AG Demir Direk | C8: 245 | F8: ASTAN | H8: *DÜZENLE menüsü içindeki araçlar kullanılarak mesafe ölçümü yapılabilir, saha tespiti ile ilgli yere açıklama yazılabilir. Yanlış eklenen çizgi, açıklama veya fotoğraf silinebilir. Taşıma butonu ile eklenen fotoğraf konum hatasından dolayı farklı yerde çıkarsa olması gereken yere taşınabilir.
A9: 5.5.1-7 | B9: 12I - Uzun Tip AG Demir Direk | C9: 258 | F9: ATS | H9: *ADRESE git butonuna tıkladıktan sonra harita üzerinde bir noktaya tıklanınca oraya yol tarifi alır.
A10: 5.5.1-8 | B10: 12U - Uzun Tip AG Demir Direk | C10: 315 | F10: AZRAM | H10: *KONUM butonu cihaz konumunu gösterir.
A11: 5.5.1-9 | B11: K1 - Uzun Tip AG Demir Direk | C11: 326 | F11: BİÇİM | H11: *Saha tespiti ile ilgili fotoğraflar, proje ve çizim araçları ile eklenen veriler tamamlandıktan sonra KAYDET butonuna basılırsa seçilmeyen fotoğraf simgeleri ekrandan kaybolur.
A12: 5.5.1-10 | B12: K2 - Uzun Tip AG Demir Direk | C12: 504 | F12: BİNER-MANKAR | H12: *RAPOR butonu içinde bulunan penereden oluşturulacak rapora isim verilebilir. KMZ raporu ile pencere içinde kalan çizimler ve fotoğraflar kmz dosyası olarak kaydedilir. EXCEL RAPORU butonu ile açılan pencere hazırlanacak saha tespit tutanağının içeriğini anlatacak şekilde düzenlenmiş alanı içine alacak şekilde konumlandırılmalıdır. Sonrasında VERİYİ AKTAR butonuna tıklandığında bu saha rapor şablonu gösterilirse KAPAK sayfası ve seçilen fotoğraflar bilgileri ile bu şablona doldurulacaktır. (sadece seçilen fotoğraflar ve pencere alanı içinde kalan fotoğraflar şablona işlenir. seçilen her 4 fotoğraf için sf1 sayfası çoğaltılarak doldurulur. )
A13: 5.5.1-11 | B13: K3 - Uzun Tip AG Demir Direk | C13: 578 | F13: BST | H13: *Rapor şablonunda sf1 sayfasında değişiklik yapmayınız. KAPAK sayfasında içerisine fotoğraf gelecek olan hücre aralığı değiştirilmemelidir. Bunun dışında kullanıcı bu sayfayı kendine göre düzenleyebilir. (Yeraltı ve Havai hat işleri için ayrı şablon düzenlenirse iş durumuna göre ilgili şablon yüklenir daha kullanışlı olabilir.)
A14: 5.5.1-12 | B14: K4 - Uzun Tip AG Demir Direk | C14: 800 | F14: CANSEVER | H14: *Saha raporu oluşturulduktan sonra uygun olmayan imalat miktarı özet olarak kapak sayfasına doğru gelmesine dikkat edelim(kanal için elle hesaplanıp girilecek).üstteki formata uygun olarak girilen miktarlar burada alınıp takip tablosunda tutanak sayfasına eklenebilir.
A15: 5.5.1-13 | B15: K5 - Uzun Tip AG Demir Direk | C15: 914 | F15: EMEK | H15: *rapor oluşturmak için bu sayfayı silerek kullanırsanız hata vermeyecektir.
A16: 5.5.1-15 | B16: 10I" - Uzun Tip Müşterek Demir Direk | C16: 230 | F16: ENDOKS | H16: Kapak ve sf1-sf2-sf3… sayfaları seçilerek pdf kaydedip rapor tamamlanır.
A17: 5.5.1-16 | B17: 10U" - Uzun Tip Müşterek Demir Direk | C17: 280 | F17: ERBU | H17: *rapor oluşturmak için bu sayfayı silerek kullanırsanız hata vermeyecektir.
A18: 5.5.1-17 | B18: 12I" - Uzun Tip Müşterek Demir Direk | C18: 298 | F18: ERGRİD
A19: 5.5.1-18 | B19: 12U" - Uzun Tip Müşterek Demir Direk | C19: 362 | F19: ERKEL
A20: 5.5.1-19 | B20: K1" - Uzun Tip Müşterek Demir Direk | C20: 373 | F20: ERKSİS
A21: 5.5.1-20 | B21: K2" - Uzun Tip Müşterek Demir Direk | C21: 449 | F21: EVD-UYAR
A22: 5.5.1-21 | B22: K3" - Uzun Tip Müşterek Demir Direk | C22: 566 | F22: GENÇ VİZYON
A23: 5.5.1-22 | B23: K4" - Uzun Tip Müşterek Demir Direk | C23: 790 | F23: HASACAR
A24: 5.5.1-23 | B24: K5" - Uzun Tip Müşterek Demir Direk | C24: 952 | F24: HİPAR
A25: 5.5.1-28 | B25: T-35 - Kaynaklı Uzun Trafo Direği TEDAŞ | C25: 995 | F25: HİSÇE
A26: 5.5.1-2 | B26: II - Büyük Aralıklı Hava Hattı Direkleri | F26: IŞIK
A27: kaynaklı enh direği SW | B27: T-10(Sw) 3xSw. İletkenli OG Taşıyıcı | C27: 258 | F27: İSMAİL ACAR
A28: kaynaklı enh direği SW | B28: T-12(Sw) 3xSw. İletkenli OG Taşıyıcı | C28: 306 | F28: KBG
A29: kaynaklı enh direği SW | B29: T-14(Sw) 3xSw. İletkenli OG Taşıyıcı | C29: 370 | F29: MACAR
A30: kaynaklı enh direği SW | B30: T-16(Sw) 3xSw. İletkenli OG Taşıyıcı | C30: 426 | F30: MESSAD
A31: kaynaklı enh direği SW | B31: T-18(Sw) 3xSw. İletkenli OG Taşıyıcı | C31: 473 | F31: ÖZLER EFE
A32: kaynaklı enh direği SW | B32: T-20(Sw) 3xSw. İletkenli OG Taşıyıcı | C32: 564 | F32: RAMKA
A33: kaynaklı enh direği SW | B33: D-10(Sw) 3xSw. İletkenli OG Durdurucu | C33: 279 | F33: SBF
A34: kaynaklı enh direği SW | B34: D-12(Sw) 3xSw. İletkenli OG Durdurucu | C34: 344 | F34: VOLDAĞ
A35: kaynaklı enh direği SW | B35: D-14(Sw) 3xSw. İletkenli OG Durdurucu | C35: 418 | F35: YDC
A36: kaynaklı enh direği SW | B36: D-16(Sw) 3xSw. İletkenli OG Durdurucu | C36: 506 | F36: YEKEL
A37: kaynaklı enh direği SW | B37: D-18(Sw) 3xSw. İletkenli OG Durdurucu | C37: 591
A38: kaynaklı enh direği SW | B38: D-20(Sw) 3xSw. İletkenli OG Durdurucu | C38: 671
A39: kaynaklı enh direği SW | B39: N-10(Sw) 3xSw. İletkenli OG Nihayet | C39: 293
A40: kaynaklı enh direği SW | B40: N-12(Sw) 3xSw. İletkenli OG Nihayet | C40: 366
...

Sheet KAPAK
E1: CK ENERJİ TESİS YAPIM İŞLERİ GRUP DİREKTÖRLÜĞÜ
E2: SAHA TEKNİK TESPİT VE UYGUNSUZLUK RAPORU
B3: TARİH : | D3: =+TODAY() -> 46048 | I3: ALTYÜKLENİCİ :
B4: SAYI : | I4: PROJE NO :
B5: İŞ ADI :
B6: TESPİT AÇIKLAMALARI :
B7: 1
B8: 2
B9: 3
B10: 4
B11: 5
B12: 6
B13: Poz No | C13: Poz tanımı | H13: Birim Ağ. | I13: Miktar | K13: Poz No | L13: Poz tanımı | Q13: Birim Ağ. | R13: Miktar
B14: 40.1.1 | C14: TUVENAN DOLGULU KABLO KANALI | K14: 40.2.4 | L14: PARKE KAPLAMALI TUVENAN KABLO KANALI
B15: 40.2 | C15: TOPRAK DOLGULU KABLO KANALI | K15: 40.2.5 | L15: BETON KAPLAMALI TUVENAN KABLO KANALI
B16: 5.5.1-1 | C16: I-Şehir içi A.G ve O.G Müşterek Direkleri | I16: =+SUMPRODUCT(Q17:Q26,R17:R26)+SUMPRODUCT(H17:H26,I17:I26) -> 0 | K16: 5.5.1-2 | L16: II - Büyük Aralıklı Hava Hattı Direkleri | R16: 0
B17: 5.5.1-28 | C17: T-35 - Kaynaklı Uzun Trafo Direği | H17: 995 | K17: 5.5.1-15 | L17: 10I" - Uzun Tip Müşterek Demir Direk | Q17: 230
B18: 5.5.1-5 | C18: 10I - Uzun Tip AG Demir Direk | H18: 207 | K18: 5.5.1-16 | L18: 10U" - Uzun Tip Müşterek Demir Direk | Q18: 280
B19: 5.5.1-6 | C19: 10U - Uzun Tip AG Demir Direk | H19: 245 | K19: 5.5.1-17 | L19: 12I" - Uzun Tip Müşterek Demir Direk | Q19: 298
B20: 5.5.1-7 | C20: 12I - Uzun Tip AG Demir Direk | H20: 258 | K20: 5.5.1-18 | L20: 12U" - Uzun Tip Müşterek Demir Direk | Q20: 362
B21: 5.5.1-8 | C21: 12U - Uzun Tip AG Demir Direk | H21: 315 | K21: 5.5.1-19 | L21: K1" - Uzun Tip Müşterek Demir Direk | Q21: 373
B22: 5.5.1-9 | C22: K1 - Uzun Tip AG Demir Direk | H22: 326 | K22: 5.5.1-20 | L22: K2" - Uzun Tip Müşterek Demir Direk | Q22: 449
B23: 5.5.1-10 | C23: K2 - Uzun Tip AG Demir Direk | H23: 504 | K23: 5.5.1-21 | L23: K3" - Uzun Tip Müşterek Demir Direk | Q23: 566
B24: 5.5.1-11 | C24: K3 - Uzun Tip AG Demir Direk | H24: 578 | K24: 5.5.1-22 | L24: K4" - Uzun Tip Müşterek Demir Direk | Q24: 790
B25: 5.5.1-12 | C25: K4 - Uzun Tip AG Demir Direk | H25: 800 | K25: 5.5.1-23 | L25: K5" - Uzun Tip Müşterek Demir Direk | Q25: 952
B26: 5.5.1-13 | C26: K5 - Uzun Tip AG Demir Direk | H26: 914
M28: TESPİTİ YAPAN
M29: isim / imza
B31: B32:R60

Sheet sf1
A1: 1 | B1: 1
B2: 2 | C2: FOTO : | E2: maps | F2: ENLEM | H2: BOYLAM | J2: FOTO : | L2: maps | M2: ENLEM | O2: BOYLAM
B3: 3
B4: 4
B5: 5
B6: 6
B7: 7
B8: 8
B9: 9
B10: 10
B11: 11
B12: 12
B13: 13
B14: 14
... B31: 31
B32: 32 | C32: FOTO : | E32: maps | F32: ENLEM | H32: BOYLAM | J32: FOTO : | L32: maps | M32: ENLEM | O32: BOYLAM
B33: 33
B34: 34
B35: 35
B36: 36
B37: 37
B38: 38
B39: 39
B40: 40
B41: 41
B42: 42
B43: 43
B44: 44
... B60: 60
